<sdf version='1.7'>
  <model name='ackermann_scout'>
    <allow_auto_disable>false</allow_auto_disable>

    <link name='base_link'>
      <inertial>
        <pose>0 0 0 0 0 0</pose>
        <mass>50.0</mass>
        <inertia>
          <ixx>2.288641</ixx>
          <ixy>0.0</ixy>
          <ixz>0.0</ixz>
          <iyy>5.103976</iyy>
          <iyz>0.0</iyz>
          <izz>3.431465</izz>
        </inertia>
      </inertial>
      <gravity>true</gravity>
      <self_collide>false</self_collide>

      <collision name='base_link_collision'>
        <pose>0 0 0.008 0 0 0</pose>
        <geometry>
          <box>
            <size>0.925 0.38 0.21</size>
          </box>
        </geometry>
      </collision>
      <collision name='base_link_collision_1'>
        <pose>0 0 0.035 0 0 0</pose>
        <geometry>
          <box>
            <size>0.154167 0.627 0.07</size>
          </box>
        </geometry>
      </collision>
      <collision name='top_plate_collision'>
        <pose>0 0 0.12 0 0 0</pose>
        <geometry>
          <mesh>
            <uri>model://scout_description/meshes/top_plate.stl</uri>
          </mesh>
        </geometry>
      </collision>
      <collision name='laser_mount_collision'>
        <pose>0.1206 0 0.1785 0 0 0</pose>
        <geometry>
          <box>
            <size>0.1 0.108 0.117</size>
          </box>
        </geometry>
      </collision>
      <collision name='laser_collision'>
        <pose>0.1558 0 0.1766 3.14159 0 0</pose>
        <geometry>
          <mesh>
            <uri>model://scout_description/meshes/accessories/ydlidar.dae</uri>
          </mesh>
        </geometry>
      </collision>

      <visual name='base_link_visual'>
        <geometry>
          <mesh>
            <uri>model://scout_description/meshes/base_link.dae</uri>
          </mesh>
        </geometry>
      </visual>
      <visual name='top_plate_visual'>
        <pose>0 0 0.12 0 0 0</pose>
        <geometry>
          <mesh>
            <uri>model://scout_description/meshes/top_plate.dae</uri>
          </mesh>
        </geometry>
      </visual>
      <visual name='laser_mount_visual'>
        <pose>0.1206 0 0.12 0 0 -1.57079</pose>
        <geometry>
          <mesh>
            <uri>model://scout_description/meshes/accessories/ydlidar_mount.dae</uri>
          </mesh>
        </geometry>
      </visual>
      <visual name='laser_visual'>
        <pose>0.1558 0 0.1766 3.14159 0 0</pose>
        <geometry>
          <mesh>
            <uri>model://scout_description/meshes/accessories/ydlidar.dae</uri>
          </mesh>
        </geometry>
      </visual>
      <visual name='sensor_arch_visual'>
        <pose>0 0 0.42 0 0 0</pose>
        <geometry>
          <mesh>
            <scale>1 1 1</scale>
            <uri>model://scout_description/meshes/accessories/300_mm_sensor_arch.dae</uri>
          </mesh>
        </geometry>
      </visual>
      <visual name='vlp16_mount_left_support_visual'>
        <pose>0 0.04 0.48 0 0 0</pose>
        <geometry>
          <box>
            <size>0.012 0.012 0.12</size>
          </box>
        </geometry>
        <material>
          <ambient>1 1 1 1</ambient>
          <diffuse>1 1 1 1</diffuse>
        </material>
      </visual>
      <visual name='vlp16_mount_right_support_visual'>
        <pose>0 -0.04 0.48 0 0 0</pose>
        <geometry>
          <box>
            <size>0.012 0.012 0.12</size>
          </box>
        </geometry>
        <material>
          <ambient>1 1 1 1</ambient>
          <diffuse>1 1 1 1</diffuse>
        </material>
      </visual>
      <visual name='vlp16_base_1_visual'>
        <pose>0 0 0.54 0 0 0</pose>
        <geometry>
          <mesh>
            <uri>package://velodyne_description/meshes/VLP16_base_1.dae</uri>
          </mesh>
        </geometry>
      </visual>
      <visual name='vlp16_base_2_visual'>
        <pose>0 0 0.54 0 0 0</pose>
        <geometry>
          <mesh>
            <uri>package://velodyne_description/meshes/VLP16_base_2.dae</uri>
          </mesh>
        </geometry>
      </visual>
      <visual name='vlp16_scan_visual'>
        <pose>0 0 0.54 0 0 0</pose>
        <geometry>
          <mesh>
            <uri>package://velodyne_description/meshes/VLP16_scan.dae</uri>
          </mesh>
        </geometry>
      </visual>

    </link>

    <link name='front_left_steering_block_link'>
      <pose relative_to='front_left_steering_joint'>0 0 0 0 0 0</pose>
      <gravity>true</gravity>
      <self_collide>false</self_collide>
      <inertial>
        <pose>0 0 0 0 0 0</pose>
        <mass>1.0</mass>
        <inertia>
          <ixx>1.0</ixx>
          <ixy>0.0</ixy>
          <ixz>0.0</ixz>
          <iyy>1.0</iyy>
          <iyz>0.0</iyz>
          <izz>1.0</izz>
        </inertia>
      </inertial>
      <collision name='front_left_steering_block_collision'>
        <geometry>
          <cylinder>
            <radius>0.03</radius>
            <length>0.05</length>
          </cylinder>
        </geometry>
      </collision>
      <visual name='front_left_steering_block_visual'>
        <geometry>
          <cylinder>
            <radius>0.03</radius>
            <length>0.05</length>
          </cylinder>
        </geometry>
      </visual>
    </link>

    <link name='front_right_steering_block_link'>
      <pose relative_to='front_right_steering_joint'>0 0 0 0 0 0</pose>
      <gravity>true</gravity>
      <self_collide>false</self_collide>
      <inertial>
        <pose>0 0 0 0 0 0</pose>
        <mass>1.0</mass>
        <inertia>
          <ixx>1.0</ixx>
          <ixy>0.0</ixy>
          <ixz>0.0</ixz>
          <iyy>1.0</iyy>
          <iyz>0.0</iyz>
          <izz>1.0</izz>
        </inertia>
      </inertial>
      <collision name='front_right_steering_block_collision'>
        <geometry>
          <cylinder>
            <radius>0.03</radius>
            <length>0.05</length>
          </cylinder>
        </geometry>
      </collision>
      <visual name='front_right_steering_block_visual'>
        <geometry>
          <cylinder>
            <radius>0.03</radius>
            <length>0.05</length>
          </cylinder>
        </geometry>
      </visual>
    </link>

    <link name='front_left_wheel_link'>
      <pose relative_to='front_left_wheel_joint'>0 0 0 0 0 0</pose>
      <gravity>true</gravity>
      <self_collide>false</self_collide>
      <inertial>
        <pose>0 0 0 0 0 0</pose>
        <mass>8.0</mass>
        <inertia>
          <ixx>0.1171</ixx>
          <ixy>0.0</ixy>
          <ixz>0.0</ixz>
          <iyy>0.1361</iyy>
          <iyz>0.0</iyz>
          <izz>0.1171</izz>
        </inertia>
      </inertial>
      <collision name='front_left_wheel_collision'>
        <pose>0 0 0 1.570795 0 0</pose>
        <geometry>
          <cylinder>
            <radius>0.16459</radius>
            <length>0.11653</length>
          </cylinder>
        </geometry>
        <surface>
          <contact>
            <ode>
              <kp>1000000000.0</kp>
              <kd>0.0</kd>
              <min_depth>0.001</min_depth>
            </ode>
          </contact>
          <friction>
            <ode>
              <mu>8.0</mu>
              <mu2>6.0</mu2>
              <fdir1>1 0 0</fdir1>
            </ode>
          </friction>
        </surface>
      </collision>
      <visual name='front_left_wheel_visual'>
        <pose>0 0 0 0 0 0</pose>
        <geometry>
          <mesh>
            <scale>1 1 1</scale>
            <uri>model://scout_description/meshes/wheel.dae</uri>
          </mesh>
        </geometry>
      </visual>
    </link>

    <link name='front_right_wheel_link'>
      <pose relative_to='front_right_wheel_joint'>0 0 0 0 0 0</pose>
      <gravity>true</gravity>
      <self_collide>false</self_collide>
      <inertial>
        <pose>0 0 0 0 0 0</pose>
        <mass>8.0</mass>
        <inertia>
          <ixx>0.1171</ixx>
          <ixy>0.0</ixy>
          <ixz>0.0</ixz>
          <iyy>0.1361</iyy>
          <iyz>0.0</iyz>
          <izz>0.1171</izz>
        </inertia>
      </inertial>
      <collision name='front_right_wheel_collision'>
        <pose>0 0 0 1.570795 0 0</pose>
        <geometry>
          <cylinder>
            <radius>0.16459</radius>
            <length>0.11653</length>
          </cylinder>
        </geometry>
        <surface>
          <contact>
            <ode>
              <kp>1000000000.0</kp>
              <kd>0.0</kd>
              <min_depth>0.001</min_depth>
            </ode>
          </contact>
          <friction>
            <ode>
              <mu>8.0</mu>
              <mu2>6.0</mu2>
              <fdir1>1 0 0</fdir1>
            </ode>
          </friction>
        </surface>
      </collision>
      <visual name='front_right_wheel_visual'>
        <pose>0 0 0 3.14159 0 0</pose>
        <geometry>
          <mesh>
            <scale>1 1 1</scale>
            <uri>model://scout_description/meshes/wheel.dae</uri>
          </mesh>
        </geometry>
      </visual>
    </link>

    <link name='rear_left_wheel_link'>
      <pose relative_to='rear_left_wheel_joint'>0 0 0 0 0 0</pose>
      <gravity>true</gravity>
      <self_collide>false</self_collide>
      <inertial>
        <pose>0 0 0 0 0 0</pose>
        <mass>8.0</mass>
        <inertia>
          <ixx>0.1171</ixx>
          <ixy>0.0</ixy>
          <ixz>0.0</ixz>
          <iyy>0.1361</iyy>
          <iyz>0.0</iyz>
          <izz>0.1171</izz>
        </inertia>
      </inertial>
      <collision name='rear_left_wheel_collision'>
        <pose>0 0 0 1.570795 0 0</pose>
        <geometry>
          <cylinder>
            <radius>0.16459</radius>
            <length>0.11653</length>
          </cylinder>
        </geometry>
        <surface>
          <contact>
            <ode>
              <kp>1000000000.0</kp>
              <kd>0.0</kd>
              <min_depth>0.001</min_depth>
            </ode>
          </contact>
          <friction>
            <ode>
              <mu>8.0</mu>
              <mu2>6.0</mu2>
              <fdir1>1 0 0</fdir1>
            </ode>
          </friction>
        </surface>
      </collision>
      <visual name='rear_left_wheel_visual'>
        <geometry>
          <mesh>
            <uri>model://scout_description/meshes/wheel.dae</uri>
          </mesh>
        </geometry>
      </visual>
    </link>

    <link name='rear_right_wheel_link'>
      <pose relative_to='rear_right_wheel_joint'>0 0 0 0 0 0</pose>
      <gravity>true</gravity>
      <self_collide>false</self_collide>
      <inertial>
        <pose>0 0 0 0 0 0</pose>
        <mass>8.0</mass>
        <inertia>
          <ixx>0.1171</ixx>
          <ixy>0.0</ixy>
          <ixz>0.0</ixz>
          <iyy>0.1361</iyy>
          <iyz>0.0</iyz>
          <izz>0.1171</izz>
        </inertia>
      </inertial>
      <collision name='rear_right_wheel_collision'>
        <pose>0 0 0 1.570795 0 0</pose>
        <geometry>
          <cylinder>
            <radius>0.16459</radius>
            <length>0.11653</length>
          </cylinder>
        </geometry>
        <surface>
          <contact>
            <ode>
              <kp>1000000000.0</kp>
              <kd>0.0</kd>
              <min_depth>0.001</min_depth>
            </ode>
          </contact>
          <friction>
            <ode>
              <mu>8.0</mu>
              <mu2>6.0</mu2>
              <fdir1>1 0 0</fdir1>
            </ode>
          </friction>
        </surface>
      </collision>
      <visual name='rear_right_wheel_visual'>
        <pose>0 0 0 3.14159 0 0</pose>
        <geometry>
          <mesh>
            <uri>model://scout_description/meshes/wheel.dae</uri>
          </mesh>
        </geometry>
      </visual>
    </link>

    <joint name='front_left_steering_joint' type='revolute'>
      <pose relative_to='base_link'>0.249 0.29153 -0.0702 0 0 0</pose>
      <parent>base_link</parent>
      <child>front_left_steering_block_link</child>
      <axis>
        <xyz>0 0 1</xyz>
        <limit>
          <lower>-0.7</lower>
          <upper>0.7</upper>
          <effort>200</effort>
          <velocity>1.5</velocity>
        </limit>
        <dynamics>
          <damping>2.0</damping>
        </dynamics>
      </axis>
    </joint>

    <joint name='front_right_steering_joint' type='revolute'>
      <pose relative_to='base_link'>0.249 -0.29153 -0.0702 0 0 0</pose>
      <parent>base_link</parent>
      <child>front_right_steering_block_link</child>
      <axis>
        <xyz>0 0 1</xyz>
        <limit>
          <lower>-0.7</lower>
          <upper>0.7</upper>
          <effort>200</effort>
          <velocity>1.5</velocity>
        </limit>
        <dynamics>
          <damping>2.0</damping>
        </dynamics>
      </axis>
    </joint>

    <joint name='front_left_wheel_joint' type='revolute'>
      <pose relative_to='front_left_steering_block_link'>0 0 0 0 0 0</pose>
      <parent>front_left_steering_block_link</parent>
      <child>front_left_wheel_link</child>
      <axis>
        <xyz>0 1 0</xyz>
        <limit>
          <lower>-10000000000000000</lower>
          <upper>10000000000000000</upper>
        </limit>
        <dynamics>
          <damping>0</damping>
          <friction>20</friction>
          <spring_reference>0</spring_reference>
          <spring_stiffness>0</spring_stiffness>
        </dynamics>
      </axis>
    </joint>

    <joint name='front_right_wheel_joint' type='revolute'>
      <pose relative_to='front_right_steering_block_link'>0 0 0 0 0 0</pose>
      <parent>front_right_steering_block_link</parent>
      <child>front_right_wheel_link</child>
      <axis>
        <xyz>0 1 0</xyz>
        <limit>
          <lower>-10000000000000000</lower>
          <upper>10000000000000000</upper>
        </limit>
        <dynamics>
          <damping>0</damping>
          <friction>20</friction>
          <spring_reference>0</spring_reference>
          <spring_stiffness>0</spring_stiffness>
        </dynamics>
      </axis>
    </joint>

    <joint name='rear_left_wheel_joint' type='revolute'>
      <pose relative_to='base_link'>-0.249 0.29153 -0.0702 0 0 0</pose>
      <parent>base_link</parent>
      <child>rear_left_wheel_link</child>
      <axis>
        <xyz>0 1 0</xyz>
        <limit>
          <lower>-10000000000000000</lower>
          <upper>10000000000000000</upper>
        </limit>
      </axis>
    </joint>

    <joint name='rear_right_wheel_joint' type='revolute'>
      <pose relative_to='base_link'>-0.249 -0.29153 -0.0702 0 0 0</pose>
      <parent>base_link</parent>
      <child>rear_right_wheel_link</child>
      <axis>
        <xyz>0 1 0</xyz>
        <limit>
          <lower>-10000000000000000</lower>
          <upper>10000000000000000</upper>
        </limit>
      </axis>
    </joint>

    <plugin name='ackermann_drive' filename='libagribot_ackermann_rpp_drive.so'>
      <ros>
        <namespace>/</namespace>
      </ros>
      <cmd_vel_topic>/nav2/cmd_vel_safe</cmd_vel_topic>
      <odom_topic>/odom</odom_topic>
      <joint_state_topic>/joint_states</joint_state_topic>
      <odom_frame>odom</odom_frame>
      <base_frame>base_link</base_frame>
      <wheelbase>0.498</wheelbase>
      <track_width>0.58306</track_width>
      <wheel_radius>0.16459</wheel_radius>
      <max_steering_angle>0.6</max_steering_angle>
      <max_steering_rate>1.2</max_steering_rate>
      <max_speed>1.0</max_speed>
      <max_accel>1.5</max_accel>
      <min_speed_for_curvature>0.05</min_speed_for_curvature>
      <command_timeout>1.5</command_timeout>
      <publish_rate>30.0</publish_rate>
      <publish_tf>true</publish_tf>
      <wheel_torque>200.0</wheel_torque>
      <sensor_model_name>ackermann_scout_sensor</sensor_model_name>
    </plugin>
  </model>
</sdf>
