<sdf version='1.7'>
  <model name='scout'>
    <link name='base_link'>
      <inertial>
        <pose>0.000487 -2.1e-05 0.000553 0 -0 0</pose>
        <mass>50.1572</mass>
        <inertia>
          <ixx>2.2936</ixx>
          <ixy>0.000162565</ixy>
          <ixz>-0.00429864</ixz>
          <iyy>5.11278</iyy>
          <iyz>0.000184235</iyz>
          <izz>3.43533</izz>
        </inertia>
      </inertial>
      <collision name='base_link_collision'>
        <pose>0 0 0.008 0 -0 0</pose>
        <geometry>
          <box>
            <size>0.925 0.38 0.21</size>
          </box>
        </geometry>
        <surface>
          <contact>
            <ode/>
          </contact>
          <friction>
            <ode/>
          </friction>
        </surface>
      </collision>
      <collision name='base_link_collision_1'>
        <pose>0 0 0.035 0 -0 0</pose>
        <geometry>
          <box>
            <size>0.154167 0.627 0.07</size>
          </box>
        </geometry>
        <surface>
          <contact>
            <ode/>
          </contact>
          <friction>
            <ode/>
          </friction>
        </surface>
      </collision>
      <collision name='base_link_fixed_joint_lump__top_plate_link_collision_2'>
        <pose>0 0 0.12 0 -0 0</pose>
        <geometry>
          <mesh>
            <scale>1 1 1</scale>
            <uri>model://scout_description/meshes/top_plate.stl</uri>
          </mesh>
        </geometry>
      </collision>
      <collision name='base_link_fixed_joint_lump__base_laser_mount_collision_3'>
        <pose>0.1206 0 0.1785 0 -0 0</pose>
        <geometry>
          <box>
            <size>0.1 0.108 0.117</size>
          </box>
        </geometry>
      </collision>
      <collision name='base_link_fixed_joint_lump__base_laser_collision_4'>
        <pose>0.1558 0 0.1766 3.14159 -0 0</pose>
        <geometry>
          <mesh>
            <scale>1 1 1</scale>
            <uri>model://scout_description/meshes/accessories/ydlidar.dae</uri>
          </mesh>
        </geometry>
        <surface>
          <contact>
            <ode/>
          </contact>
          <friction>
            <ode/>
          </friction>
        </surface>
      </collision>
      <visual name='base_link_visual'>
        <pose>0 0 0 0 -0 0</pose>
        <geometry>
          <mesh>
            <scale>1 1 1</scale>
            <uri>model://scout_description/meshes/base_link.dae</uri>
          </mesh>
        </geometry>
      </visual>
      <visual name='base_link_fixed_joint_lump__top_plate_link_visual_1'>
        <pose>0 0 0.12 0 -0 0</pose>
        <geometry>
          <mesh>
            <scale>1 1 1</scale>
            <uri>model://scout_description/meshes/top_plate.dae</uri>
          </mesh>
        </geometry>
      </visual>
      <visual name='base_link_fixed_joint_lump__base_laser_mount_visual_2'>
        <pose>0.1206 0 0.12 0 0 -1.57079</pose>
        <geometry>
          <mesh>
            <scale>1 1 1</scale>
            <uri>model://scout_description/meshes/accessories/ydlidar_mount.dae</uri>
          </mesh>
        </geometry>
      </visual>
      <visual name='base_link_fixed_joint_lump__base_laser_visual_3'>
        <pose>0.1558 0 0.1766 3.14159 -0 0</pose>
        <geometry>
          <mesh>
            <scale>1 1 1</scale>
            <uri>model://scout_description/meshes/accessories/ydlidar.dae</uri>
          </mesh>
        </geometry>
      </visual>
      <visual name='base_link_fixed_joint_lump__sensor_arch_mount_link_visual_4'>
        <pose>0 0 0.42 0 -0 0</pose>
        <geometry>
          <mesh>
            <scale>1 1 1</scale>
            <uri>model://scout_description/meshes/accessories/300_mm_sensor_arch.dae</uri>
          </mesh>
        </geometry>
      </visual>
      <sensor name='gps_sensor' type='gps'>
        <always_on>1</always_on>
        <update_rate>40</update_rate>
        <visualize>0</visualize>
        <gps>
          <position_sensing>
            <horizontal>
              <noise type='gaussian'>
                <mean>0</mean>
                <stddev>0.0001</stddev>
              </noise>
            </horizontal>
            <vertical>
              <noise type='gaussian'>
                <mean>0</mean>
                <stddev>0.0001</stddev>
              </noise>
            </vertical>
          </position_sensing>
        </gps>
        <plugin name='gps_controller' filename='libgazebo_ros_gps_sensor.so'>
          <ros>
            <namespace>/</namespace>
            <remapping>~/out:=navsat/fix</remapping>
          </ros>
        </plugin>
      </sensor>
      <sensor name='imu_sensor' type='imu'>
        <always_on>1</always_on>
        <update_rate>50</update_rate>
        <visualize>0</visualize>
        <imu>
          <angular_velocity>
            <x>
              <noise type='gaussian'>
                <mean>0</mean>
                <stddev>0.005</stddev>
              </noise>
            </x>
            <y>
              <noise type='gaussian'>
                <mean>0</mean>
                <stddev>0.005</stddev>
              </noise>
            </y>
            <z>
              <noise type='gaussian'>
                <mean>0</mean>
                <stddev>0.005</stddev>
              </noise>
            </z>
          </angular_velocity>
          <linear_acceleration>
            <x>
              <noise type='gaussian'>
                <mean>0</mean>
                <stddev>0.005</stddev>
              </noise>
            </x>
            <y>
              <noise type='gaussian'>
                <mean>0</mean>
                <stddev>0.005</stddev>
              </noise>
            </y>
            <z>
              <noise type='gaussian'>
                <mean>0</mean>
                <stddev>0.005</stddev>
              </noise>
            </z>
          </linear_acceleration>
        </imu>
        <plugin name='imu_controller' filename='libgazebo_ros_imu_sensor.so'>
          <ros>
            <namespace>/</namespace>
            <remapping>~/out:=imu/data</remapping>
          </ros>
          <frame_name>imu_link</frame_name>
        </plugin>
        <pose>0.19 0 0.149 -3.14159 -1.57079 7e-06</pose>
      </sensor>
      <sensor name='base_laser' type='ray'>
        <visualize>1</visualize>
        <update_rate>50</update_rate>
        <ray>
          <scan>
            <horizontal>
              <samples>720</samples>
              <resolution>1</resolution>
              <min_angle>-1.5708</min_angle>
              <max_angle>1.5708</max_angle>
            </horizontal>
          </scan>
          <range>
            <min>0.65</min>
            <max>30</max>
            <resolution>0.01</resolution>
          </range>
          <noise>
            <type>gaussian</type>
            <mean>0</mean>
            <stddev>0.001</stddev>
          </noise>
        </ray>
        <plugin name='base_laser_scan' filename='libgazebo_ros_ray_sensor.so'>
          <ros>
            <namespace>/</namespace>
            <remapping>~/out:=scan</remapping>
          </ros>
          <frame_name>base_laser</frame_name>
          <output_type>sensor_msgs/LaserScan</output_type>
        </plugin>
        <pose>0.1558 0 0.1766 3.14159 -0 0</pose>
      </sensor>
      <gravity>0</gravity>
      <sensor name='camera_realsense_depth' type='depth'>
        <update_rate>30</update_rate>
        <camera>
          <horizontal_fov>1.51844</horizontal_fov>
          <image>
            <width>640</width>
            <height>480</height>
            <format>RGB_INT8</format>
          </image>
          <depth_camera/>
          <clip>
            <near>0.01</near>
            <far>50</far>
          </clip>
          <vertical_fov>1.0122901111111111</vertical_fov>
        </camera>
        <plugin name='kinect_controller' filename='libgazebo_ros_camera.so'>
          <ros>
            <namespace>/</namespace>
            <remapping>camera/image_raw:=camera/color/image_raw</remapping>
            <remapping>camera/camera_info:=camera/color/camera_info</remapping>
            <remapping>camera/depth/image_raw:=camera/depth/image_rect_raw</remapping>
            <remapping>camera/depth/camera_info:=camera/depth/camera_info</remapping>
            <remapping>camera/points:=camera/depth/color/points</remapping>
          </ros>
          <camera_name>camera</camera_name>
          <frame_name>camera_realsense_gazebo</frame_name>
          <min_depth>0.105</min_depth>
          <max_depth>8.0</max_depth>
          <hack_baseline>0.0</hack_baseline>
        </plugin>
        <pose>0.025 0 0.42 0 -0 0</pose>
      </sensor>
    </link>
    <joint name='front_left_wheel' type='revolute'>
      <pose relative_to='base_link'>0.249 0.29153 -0.0702 0 -0 0</pose>
      <parent>base_link</parent>
      <child>front_left_wheel_link</child>
      <axis>
        <xyz>0 1 0</xyz>
        <limit>
          <lower>-1e+16</lower>
          <upper>1e+16</upper>
        </limit>
        <dynamics>
          <damping>0</damping>
          <friction>20</friction>
          <spring_reference>0</spring_reference>
          <spring_stiffness>0</spring_stiffness>
        </dynamics>
      </axis>
    </joint>
    <link name='front_left_wheel_link'>
      <pose relative_to='front_left_wheel'>0 0 0 0 -0 0</pose>
      <inertial>
        <pose>0 0 0 0 -0 0</pose>
        <mass>8</mass>
        <inertia>
          <ixx>0.1171</ixx>
          <ixy>0</ixy>
          <ixz>0</ixz>
          <iyy>0.1361</iyy>
          <iyz>0</iyz>
          <izz>0.1171</izz>
        </inertia>
      </inertial>
      <collision name='front_left_wheel_link_collision'>
        <pose>0 0 0 1.57079 -0 0</pose>
        <geometry>
          <cylinder>
            <length>0.11653</length>
            <radius>0.16459</radius>
          </cylinder>
        </geometry>
        <surface>
          <contact>
            <ode>
              <kp>1e+09</kp>
              <kd>0</kd>
              <min_depth>0.001</min_depth>
            </ode>
          </contact>
          <friction>
            <ode>
              <mu>1.8</mu>
              <mu2>1.5</mu2>
              <fdir1>1 0 0</fdir1>
            </ode>
          </friction>
        </surface>
      </collision>
      <visual name='front_left_wheel_link_visual'>
        <pose>0 0 0 0 -0 0</pose>
        <geometry>
          <mesh>
            <scale>1 1 1</scale>
            <uri>model://scout_description/meshes/wheel.dae</uri>
          </mesh>
        </geometry>
      </visual>
    </link>
    <joint name='front_right_wheel' type='revolute'>
      <pose relative_to='base_link'>0.249 -0.29153 -0.0702 0 -0 0</pose>
      <parent>base_link</parent>
      <child>front_right_wheel_link</child>
      <axis>
        <xyz>0 1 0</xyz>
        <limit>
          <lower>-1e+16</lower>
          <upper>1e+16</upper>
        </limit>
        <dynamics>
          <damping>0</damping>
          <friction>20</friction>
          <spring_reference>0</spring_reference>
          <spring_stiffness>0</spring_stiffness>
        </dynamics>
      </axis>
    </joint>
    <link name='front_right_wheel_link'>
      <pose relative_to='front_right_wheel'>0 0 0 0 -0 0</pose>
      <inertial>
        <pose>0 0 0 0 -0 0</pose>
        <mass>8</mass>
        <inertia>
          <ixx>0.1171</ixx>
          <ixy>0</ixy>
          <ixz>0</ixz>
          <iyy>0.1361</iyy>
          <iyz>0</iyz>
          <izz>0.1171</izz>
        </inertia>
      </inertial>
      <collision name='front_right_wheel_link_collision'>
        <pose>0 0 0 1.57079 -0 0</pose>
        <geometry>
          <cylinder>
            <length>0.11653</length>
            <radius>0.16459</radius>
          </cylinder>
        </geometry>
        <surface>
          <contact>
            <ode>
              <kp>1e+09</kp>
              <kd>0</kd>
              <min_depth>0.001</min_depth>
            </ode>
          </contact>
          <friction>
            <ode>
              <mu>1.8</mu>
              <mu2>1.5</mu2>
              <fdir1>1 0 0</fdir1>
            </ode>
          </friction>
        </surface>
      </collision>
      <visual name='front_right_wheel_link_visual'>
        <pose>0 0 0 3.14159 -0 0</pose>
        <geometry>
          <mesh>
            <scale>1 1 1</scale>
            <uri>model://scout_description/meshes/wheel.dae</uri>
          </mesh>
        </geometry>
      </visual>
    </link>
    <joint name='rear_left_wheel' type='revolute'>
      <pose relative_to='base_link'>-0.249 0.29153 -0.0702 0 -0 0</pose>
      <parent>base_link</parent>
      <child>rear_left_wheel_link</child>
      <axis>
        <xyz>0 1 0</xyz>
        <limit>
          <lower>-1e+16</lower>
          <upper>1e+16</upper>
        </limit>
        <dynamics>
          <damping>0</damping>
          <friction>20</friction>
          <spring_reference>0</spring_reference>
          <spring_stiffness>0</spring_stiffness>
        </dynamics>
      </axis>
    </joint>
    <link name='rear_left_wheel_link'>
      <pose relative_to='rear_left_wheel'>0 0 0 0 -0 0</pose>
      <inertial>
        <pose>0 0 0 0 -0 0</pose>
        <mass>8</mass>
        <inertia>
          <ixx>0.1171</ixx>
          <ixy>0</ixy>
          <ixz>0</ixz>
          <iyy>0.1361</iyy>
          <iyz>0</iyz>
          <izz>0.1171</izz>
        </inertia>
      </inertial>
      <collision name='rear_left_wheel_link_collision'>
        <pose>0 0 0 1.57079 -0 0</pose>
        <geometry>
          <cylinder>
            <length>0.11653</length>
            <radius>0.16459</radius>
          </cylinder>
        </geometry>
        <surface>
          <contact>
            <ode>
              <kp>1e+09</kp>
              <kd>0</kd>
              <min_depth>0.001</min_depth>
            </ode>
          </contact>
          <friction>
            <ode>
              <mu>1.8</mu>
              <mu2>1.5</mu2>
              <fdir1>1 0 0</fdir1>
            </ode>
          </friction>
        </surface>
      </collision>
      <visual name='rear_left_wheel_link_visual'>
        <pose>0 0 0 0 -0 0</pose>
        <geometry>
          <mesh>
            <scale>1 1 1</scale>
            <uri>model://scout_description/meshes/wheel.dae</uri>
          </mesh>
        </geometry>
      </visual>
    </link>
    <joint name='rear_right_wheel' type='revolute'>
      <pose relative_to='base_link'>-0.249 -0.29153 -0.0702 0 -0 0</pose>
      <parent>base_link</parent>
      <child>rear_right_wheel_link</child>
      <axis>
        <xyz>0 1 0</xyz>
        <limit>
          <lower>-1e+16</lower>
          <upper>1e+16</upper>
        </limit>
        <dynamics>
          <damping>0</damping>
          <friction>20</friction>
          <spring_reference>0</spring_reference>
          <spring_stiffness>0</spring_stiffness>
        </dynamics>
      </axis>
    </joint>
    <link name='rear_right_wheel_link'>
      <pose relative_to='rear_right_wheel'>0 0 0 0 -0 0</pose>
      <inertial>
        <pose>0 0 0 0 -0 0</pose>
        <mass>8</mass>
        <inertia>
          <ixx>0.1171</ixx>
          <ixy>0</ixy>
          <ixz>0</ixz>
          <iyy>0.1361</iyy>
          <iyz>0</iyz>
          <izz>0.1171</izz>
        </inertia>
      </inertial>
      <collision name='rear_right_wheel_link_collision'>
        <pose>0 0 0 1.57079 -0 0</pose>
        <geometry>
          <cylinder>
            <length>0.11653</length>
            <radius>0.16459</radius>
          </cylinder>
        </geometry>
        <surface>
          <contact>
            <ode>
              <kp>1e+09</kp>
              <kd>0</kd>
              <min_depth>0.001</min_depth>
            </ode>
          </contact>
          <friction>
            <ode>
              <mu>1.8</mu>
              <mu2>1.5</mu2>
              <fdir1>1 0 0</fdir1>
            </ode>
          </friction>
        </surface>
      </collision>
      <visual name='rear_right_wheel_link_visual'>
        <pose>0 0 0 3.14159 -0 0</pose>
        <geometry>
          <mesh>
            <scale>1 1 1</scale>
            <uri>model://scout_description/meshes/wheel.dae</uri>
          </mesh>
        </geometry>
      </visual>
    </link>
    <plugin name='scout_diff_drive' filename='libgazebo_ros_diff_drive.so'>
      <ros>
        <namespace>/</namespace>
        <remapping>cmd_vel:=cmd_vel</remapping>
        <remapping>odom:=odom</remapping>
      </ros>
      <num_wheel_pairs>2</num_wheel_pairs>
      <left_joint>front_left_wheel</left_joint>
      <right_joint>front_right_wheel</right_joint>
      <left_joint>rear_left_wheel</left_joint>
      <right_joint>rear_right_wheel</right_joint>
      <wheel_separation>0.58306</wheel_separation>
      <wheel_separation>0.58306</wheel_separation>
      <wheel_diameter>0.32918</wheel_diameter>
      <wheel_diameter>0.32918</wheel_diameter>
      <update_rate>100.0</update_rate>
      <max_wheel_torque>200.0</max_wheel_torque>
      <max_wheel_acceleration>20.0</max_wheel_acceleration>
      <publish_odom>1</publish_odom>
      <publish_odom_tf>1</publish_odom_tf>
      <publish_wheel_tf>0</publish_wheel_tf>
      <odometry_frame>odom</odometry_frame>
      <robot_base_frame>base_link</robot_base_frame>
      <covariance_x>0.0001</covariance_x>
      <covariance_y>0.0001</covariance_y>
      <covariance_yaw>0.01</covariance_yaw>
    </plugin>
    <plugin name='scout_joint_state_publisher' filename='libgazebo_ros_joint_state_publisher.so'>
      <ros>
        <namespace>/</namespace>
        <remapping>joint_states:=joint_states_gazebo</remapping>
      </ros>
      <update_rate>50.0</update_rate>
      <joint_name>front_left_wheel</joint_name>
      <joint_name>front_right_wheel</joint_name>
      <joint_name>rear_left_wheel</joint_name>
      <joint_name>rear_right_wheel</joint_name>
    </plugin>
    <plugin name='p3d' filename='libgazebo_ros_p3d.so'>
      <ros>
        <namespace>/</namespace>
        <remapping>odom:=base_pose_ground_truth</remapping>
      </ros>
      <body_name>base_link</body_name>
      <update_rate>100.0</update_rate>
    </plugin>
    <frame name='base_footprint_joint' attached_to='base_link'>
      <pose>0 0 -0.23479 0 -0 0</pose>
    </frame>
    <frame name='base_footprint' attached_to='base_footprint_joint'/>
    <frame name='front_mount_joint' attached_to='base_link'>
      <pose>0.325 0 0.112701 0 -0 0</pose>
    </frame>
    <frame name='front_mount' attached_to='front_mount_joint'/>
    <frame name='imu_joint' attached_to='base_link'>
      <pose>0.19 0 0.149 -3.14159 -1.57079 7e-06</pose>
    </frame>
    <frame name='imu_link' attached_to='imu_joint'/>
    <frame name='inertial_joint' attached_to='base_link'>
      <pose>0 0 0 0 -0 0</pose>
    </frame>
    <frame name='inertial_link' attached_to='inertial_joint'/>
    <frame name='rear_mount_joint' attached_to='base_link'>
      <pose>-0.325 0 0.112701 0 -0 0</pose>
    </frame>
    <frame name='rear_mount' attached_to='rear_mount_joint'/>
    <frame name='base_laser_joint' attached_to='base_laser_mount'>
      <pose>0.0352 0 0.0566 3.14159 -0 0</pose>
    </frame>
    <frame name='base_laser' attached_to='base_laser_joint'/>
    <frame name='laser_mount_joint' attached_to='top_plate_link'>
      <pose>0.1206 0 0 0 -0 0</pose>
    </frame>
    <frame name='base_laser_mount' attached_to='laser_mount_joint'/>
    <frame name='camera_realsense_gazebo_joint' attached_to='camera_realsense'>
      <pose>0 0 0 -1.5708 -0 -1.5708</pose>
    </frame>
    <frame name='camera_realsense_gazebo' attached_to='camera_realsense_gazebo_joint'/>
    <frame name='camera_realsense_joint' attached_to='camera_realsense_lens'>
      <pose>0.025 0 0 0 -0 0</pose>
    </frame>
    <frame name='camera_realsense' attached_to='camera_realsense_joint'/>
    <frame name='camera_realsense_lens_joint' attached_to='realsense_mountpoint'>
      <pose>0 0 0 0 -0 0</pose>
    </frame>
    <frame name='camera_realsense_lens' attached_to='camera_realsense_lens_joint'/>
    <frame name='realsense_mountpoint_joint' attached_to='sensor_arch_mount_link'>
      <pose>0 0 0 0 -0 0</pose>
    </frame>
    <frame name='realsense_mountpoint' attached_to='realsense_mountpoint_joint'/>
    <frame name='sensor_arch_mount' attached_to='sensor_arch_base_link'>
      <pose>0 0 0.3 0 -0 0</pose>
    </frame>
    <frame name='sensor_arch_mount_link' attached_to='sensor_arch_mount'/>
    <frame name='sensor_arch_base_link_joint' attached_to='top_plate_link'>
      <pose>0 0 0 0 -0 0</pose>
    </frame>
    <frame name='sensor_arch_base_link' attached_to='sensor_arch_base_link_joint'/>
    <frame name='top_plate_front_joint' attached_to='top_plate_link'>
      <pose>0.36367 0 0.00639 0 -0 0</pose>
    </frame>
    <frame name='top_plate_front_link' attached_to='top_plate_front_joint'/>
    <frame name='top_plate_rear_joint' attached_to='top_plate_link'>
      <pose>-0.36633 0 0.00639 0 -0 0</pose>
    </frame>
    <frame name='top_plate_rear_link' attached_to='top_plate_rear_joint'/>
    <frame name='top_plate_joint' attached_to='base_link'>
      <pose>0 0 0.12 0 -0 0</pose>
    </frame>
    <frame name='top_plate_link' attached_to='top_plate_joint'/>
  </model>
</sdf>
